Workbook
Name _Te: '7 - Calculs Dim. du chauffage'!$F$2
Name _Ti: '7 - Calculs Dim. du chauffage'!$F$4
Name _Tlm: '7 - Calculs Dim. du chauffage'!$D$6
Name _Tlmn: '7 - Calculs Dim. du chauffage'!$H$12
Name _Ts: '7 - Calculs Dim. du chauffage'!$F$3
Name b: '2.2 - Pont thermiques'!#REF!
Name b: '5 - Calcul des déperditions'!$K$2
Name b: #REF!
Name Delta_T: '4 - Renouvellement d''air'!$C$15
Name Em: #REF!
Name Ep: #REF!
Name HRA: '4 - Renouvellement d''air'!$C$14
Name Text: '5 - Calcul des déperditions'!$K$4
Name Tint: '5 - Calcul des déperditions'!$K$3
Name val_1: #REF!
Name val_2: #REF!

Sheet 0 - Page de Garde

Sheet 1 - Métré des Surfaces Étudiées
B2: Surfaces Ouvertures Vitrée | E2: Surfaces Ouvertures Opaques
B3: Élément | C3: Vitrées | D3: Surface vitrée | E3: Élément | F3: Opaques
B4: RDC | C4: 15.355 | E4: Porte d'entrée | F4: =0.9*2.15 -> 1.935
B5: Étage | C5: 8.5 | E5: Porte cuisine | F5: =0.9*2.15 -> 1.935
B6: Combles Aménagées | C6: 1.755 | E6: Porte coulissante | F6: =0.84*2.04 -> 1.7136
B7: Vélux sur Toîture | C7: 2.1096
B8: Local non chauffé (celier) | C8: 0.57
B10: Surfaces Paroies
B11: Élément | C11: Longueur | D11: Surface BRUT | E11: Surface OUV | F11: Surface FIN
B12: Mur RDC | C12: 25.08 | D12: =SUM(C12:C12)*2.5 -> 62.7 | E12: =C4+F4+F5 -> 19.225 | F12: =D12-E12 -> 43.475
B13: Mur int LNC 1 | C13: 3.79 | D13: =SUM(C13:C13)*2.5 -> 9.475 | E13: =F6 -> 1.7136 | F13: =D13-E13 -> 7.7614
B14: Mur int LNC 2 (WC) | C14: 1.57 | D14: =SUM(C14:C14)*2.5 -> 3.925 | F14: =D14-E14 -> 3.925
B15: Mur LNC --> EXT | C15: 5.36 | D15: =SUM(C15:C15)*2.5 -> 13.4 | E15: =C8 -> 0.57 | F15: =D15-E15 -> 12.83
B16: Plancher RDC | C16: - | D16: 51.4 | F16: =D16-E16 -> 51.4
B17: Plancher LNC | C17: - | D17: 5.47 | F17: =D17-E17 -> 5.47
B18: Mur R+1 | C18: 30.44 | D18: =SUM(C18:C18)*2.4 -> 73.056 | E18: =C5 -> 8.5 | F18: =D18-E18 -> 64.556
B19: Plancher R+1 | C19: - | D19: 51.88 | F19: =D19-E19 -> 51.88
B20: Plancher R+1 --> LNC | C20: - | D20: 5.47 | F20: =D20-E20 -> 5.47
B21: Mur Combles | C21: 16.72 | D21: =SUM(C21:C21)*1.15+12.46*2 -> 44.148 | E21: =C6 -> 1.755 | F21: =D21-E21 -> 42.393
B22: Plancher Combles | C22: - | D22: 57.8 | F22: =D22-E22 -> 57.8
B23: Toîture | C23: - | D23: 72.24 | E23: =C7 -> 2.1096 | F23: =D23-E23 -> 70.1304

Sheet 2 - Propriétés des Paroies
B2: Propriétés thermiques des paroies
B3: Élément | C3: Description | D3: Résistance thermique | K3: Rtot | L3: U
D4: Couche 1 | E4: Couche 2 | F4: Couche 3 | G4: Couche 4 | H4: Couche 5 | I4: Couche 6 | J4: Air
B5: Mur extérieur | C5: Mur enduit 10mm, agglo béton, isolation 100mm laine de verre et BA13 | D5: Enduit | E5: Agglo | F5: Isolant | G5: Placo | J5: RSI RSE | K5: =SUM(D6:J6) -> 3.2950654 | L5: =1/K5 -> 0.30348412
D6: =0.01/0.72 -> 0.013888889 | E6: 0.15 | F6: =0.1/0.034 -> 2.9411765 | G6: 0.02 | J6: 0.17
B7: Cloison séparative cellier | C7: Cloison 2 BA13, isolant 100mm | D7: Plaque | E7: Isolant | J7: RSI RSI | K7: =SUM(D8:J8) -> 3.2411765 | L7: =1/K7 -> 0.30852995
D8: 0.04 | E8: =0.1/0.034 -> 2.9411765 | J8: =0.13*2 -> 0.26
B9: Cloison cellier/WC | C9: Isolation 70mm, 2 BA13 | D9: Plaque | E9: Isolant | J9: RSI RSI | K9: =SUM(D10:J10) -> 2.3588235 | L9: =1/K9 -> 0.42394015
D10: 0.04 | E10: =0.07/0.034 -> 2.0588235 | J10: =0.13*2 -> 0.26
B11: Plancher bas RDC | C11: Hourdis polystyrène 15cm, béton 5cm, mousse polyuréthane 6,5cm, chape 6cm, carrelage 1cm | D11: Béton | E11: Hourdis poly | F11: Mousse | G11: Chape | H11: Carrelage | J11: RSI RSI | K11: =1/L11 -> 5.5555556 | L11: 0.18
D12: =0.05/1.046 -> 0.047801147 | E12: =0.15/0.035 -> 4.2857143 | F12: =0.065/0.032 -> 2.03125 | G12: =0.06/1.046 -> 0.057361377 | H12: =0.01/1.046 -> 0.0095602294 | J12: =0.17*2 -> 0.34
B13: Plancher haut sur cellier | C13: Hourdis EMS, isolant 16cm en sous face | D13: Plaque | E13: Isolant | F13: Béton | G13: Hourdis | H13: Chape | I13: Carrelage | J13: RSI RSI | K13: =SUM(D14:J14) -> 5.4794099 | L13: =1/K13 -> 0.1825014
D14: 0.02 | E14: =0.16/0.034 -> 4.7058824 | F14: =0.05/1.046 -> 0.047801147 | G14: =0.15/0.502 -> 0.29880478 | H14: =0.06/1.046 -> 0.057361377 | I14: =0.01/1.046 -> 0.0095602294 | J14: =0.17*2 -> 0.34
B15: Plafond rampant combles | C15: Laine minérale soufflé 30cm, charpente, ardoises | D15: Ardoises | E15: charpente | F15: isolant | G15: plaque | J15: RSI RSE | K15: =SUM(D16:J16) -> 10.676387 | L15: =1/K15 -> 0.093664649
D16: =0.022/0.84 -> 0.026190476 | E16: =0.2/0.12 -> 1.6666667 | F16: =0.3/0.034 -> 8.8235294 | G16: 0.02 | J16: 0.14
B17: Porte d'entrée | C17: - | K17: - | L17: 1.4
B18: Porte cuisine | C18: - | K18: - | L18: 1.4
B19: Porte coulissante | C19: - | K19: - | L19: 1.4
B20: Parois vitrée | C20: - | K20: - | L20: 1.3

Sheet 2.2 - Pont thermiques
B2: Calculateur par interpolation bilinéaire :
B3: Em | C3: Ep
C4: 15 | D4: 20 | E4: 25
B5: 15 ≤ em ≤ 20 | C5: - | D5: - | E5: -
B6: 20 < em ≤ 25 | C6: 0.61 | D6: 0.72 | E6: 0.83
B7: 25 < em ≤ 30 | C7: 0.58 | D7: 0.71 | E7: 0.8
B8: Em = | C8: 20.01 | D8: =IF(AND(C8>=15,C8<=20),HLOOKUP(E8,C4:E7,2),IF(AND(C8>20,C8<=25),HLOOKUP(E8,C4:E7,3),IF(AND(C8>25,C8<=30),HLOOKUP(E8,C4:E7,4),IF(AND(C8>30),HLOOKUP(E8,C4:E7,4),"Erreur")))) -> 0.61 | E8: =IF(AND(C9>=15,C9<=20),15,IF(AND(C9>20,C9<=25),20,IF(AND(C9>25),20,"erreur trop faible"))) -> 15
B9: Ep = | C9: 20 | D9: =IF(AND(C8>=15,C8<=20),HLOOKUP(E9,C4:E7,2),IF(AND(C8>20,C8<=25),HLOOKUP(E9,C4:E7,3),IF(AND(C8>25,C8<=30),HLOOKUP(E9,C4:E7,4),IF(AND(C8>30),HLOOKUP(E9,C4:E7,4),"Erreur")))) -> 0.72 | E9: =IF(AND(C9>=15,C9<=20),20,IF(AND(C9>20,C9<=25),25,IF(AND(C9>25),25,"erreur trop faible"))) -> 20
B10: Valeur du pont thermique résultant : | E10: =((D9-D8)/(5))*(C9-E8)+D8 -> 0.72
B12: Donc : | C12: Ψ(Pb R+1) = | D12: 0.72
C13: Ψ(Pb R+2) = | D13: 0.72
B17: Calculateur par interpolation linéaire :
B18: Em | C18: Ep
C19: 15 | D19: 20 | E19: 25
B20: 15 ≤ em ≤ 30 | C20: 0.17 | D20: 0.18 | E20: 0.19
B21: Em = | C21: 16 | D21: =IF(AND(Em>=15,Em<=30),HLOOKUP(E21,C19:E20,2),"Erreur") -> #REF! | E21: =IF(AND(C22>=15,C22<=20),15,IF(AND(C22>20,C22<=25),20,IF(AND(C22>25),20,"erreur trop faible"))) -> 15
B22: Ep = | C22: 20 | D22: =IF(AND(Em>=15,Em<=30),HLOOKUP(E22,C19:E20,2),IF(AND(Em>20,Em<=25),HLOOKUP(E22,C19:E20,3),IF(AND(Em>25,Em<=30),HLOOKUP(E22,C19:E20,4),IF(AND(Em>30),HLOOKUP(E22,C19:E20,4),"Erreur")))) -> #REF! | E22: =IF(AND(C22>=15,C22<=20),20,IF(AND(C22>20,C22<=25),25,IF(AND(C22>25),25,"erreur trop faible"))) -> 20
B23: Valeur du pont thermique résultant : | E23: =((D22-D21)/(5))*(C22-E21)+D21 -> #REF!
B25: Donc : | C25: Ψ(Pb RdC) = | D25: 0.18
B29: Et pour le pignon : | D29: Ψ(Pignon-toît) = | E29: 0.18

Sheet 3 - Température LNC
B2: Élément | C2: Surface | D2: U | E2: U x S | F2: Déperditions G | H2: TLNC = | I2: 17.947793
B3: Mur Extérieurs | C3: ='1 - Métré des Surfaces Étudiées'!F15 -> 12.83 | D3: ='2 - Propriétés des Paroies'!L5 -> 0.30348412 | E3: =D3*C3 -> 3.8937012 | F3: =E3*($I$2-$I$4) -> 112.71406 | H3: TINT = | I3: 19
B4: Fenêtre | C4: =0.6*0.95 -> 0.57 | D4: ='2 - Propriétés des Paroies'!L20 -> 1.3 | E4: =D4*C4 -> 0.741 | F4: =E4*($I$2-$I$4) -> 21.450314 | H4: TEXT = | I4: -11
B5: Sol | C5: =C6 -> 5.47 | D5: ='2 - Propriétés des Paroies'!L11 -> 0.18 | E5: =D5*C5 -> 0.9846 | F5: =E5*($I$2-$I$4) -> 28.501997
B6: Plafond | C6: ='1 - Métré des Surfaces Étudiées'!F17 -> 5.47 | D6: ='2 - Propriétés des Paroies'!L13 -> 0.1825014 | E6: =D6*C6 -> 0.99828268 | F6: =E6*($I$2-$I$3) -> -1.0504003
B7: Mur Intérieurs | C7: ='1 - Métré des Surfaces Étudiées'!F13+'1 - Métré des Surfaces Étudiées'!F14 -> 11.6864 | D7: ='2 - Propriétés des Paroies'!L7 -> 0.30852995 | E7: =D7*C7 -> 3.6056044 | F7: =E7*($I$2-$I$3) -> -3.7938432
B8: Porte coulissante | C8: =0.83*2.04 -> 1.6932 | D8: ='2 - Propriétés des Paroies'!L19 -> 1.4 | E8: =D8*C8 -> 2.37048 | F8: =E8*($I$2-$I$3) -> -2.4942364
B9: Renouvellement d'air | C9: - | D9: - | E9: =1.208*1006*15/3600 -> 5.0635333 | F9: =E9*($I$2-$I$3) -> -5.3278868
B10: Apports internes | C10: - | D10: - | E10: - | F10: -150
E12: GTOT = | F12: =SUM(F3:F10) -> 0
E13: Coef b = | F13: =ROUND((I3-I2)/(I3-I4),2) -> 0.04

Sheet 4 - Renouvellement d'air
B2: Renouvellement d'air pour une maison 6 pièces
B3: Débit à extraire (m3/h)
B4: RDC | C4: 1 cuisine | D4: 135
C5: 1 WC | D5: 15
C6: 1 SDB ( buanderie) | D6: 30
B7: R+1 | C7: 1 SBD | D7: 15
C8: 1 WC | D8: 15
B9: COMBLES | C9: 1 SBD | D9: 15
B10: Total | D10: =SUM(D4:D9) -> 225
B13: Pertes par renouvellement d'air
B14: HRA | C14: =1.2*1000*(D10/3600)*1 -> 75
B15: Delta T | C15: =Tint-Text -> 30
B16: PRA | C16: =HRA*Delta_T -> 2250

Sheet 5 - Calcul des déperditions
B2: Paroi ou pont thermique | C2: Surface | D2: Longueur | E2: U | F2: Ψ | G2: Coef. Réd. b | H2: U.S.b ou Ψ.L.b | J2: Valeur calculée de b : | K2: ='3 - Température LNC'!F13 -> 0.04
B3: Pont Thermiques | H3: =SUM(H4:H10) -> 54.68414 | J3: Température intérieur : | K3: 19
B4: Angle des murs sortants courant | C4: - | D4: =3*2.5+4*2.4+4*1.15 -> 21.7 | E4: - | F4: 0.02 | G4: 1 | H4: =IF(C4="-",F4*D4*G4,C4*E4*G4) -> 0.434 | J4: Température extérieur : | K4: -11
B5: Liaison plancher sur vide sanitaire courant | C5: - | D5: 25.08 | E5: - | F5: ='2.2 - Pont thermiques'!D25 -> 0.18 | G5: 1 | H5: =IF(C5="-",F5*D5*G5,C5*E5*G5) -> 4.5144
B6: Liaison plancher bordure LNC | C6: - | D6: 5.19 | E6: - | F6: 0.65 | G6: =b -> 0.04 | H6: =IF(C6="-",F6*D6*G6,C6*E6*G6) -> 0.13494
B7: Plancher intermédiaire | C7: - | D7: 30.44 | E7: - | F7: ='2.2 - Pont thermiques'!D12 -> 0.72 | G7: 1 | H7: =IF(C7="-",F7*D7*G7,C7*E7*G7) -> 21.9168
B8: Plancher intermédiaire R+1 | C8: - | D8: 30.44 | E8: - | F8: ='2.2 - Pont thermiques'!D13 -> 0.72 | G8: 1 | H8: =IF(C8="-",F8*D8*G8,C8*E8*G8) -> 21.9168
B9: Plafond combles | C9: - | D9: =7.66*2+8.36*2 -> 32.04 | E9: - | F9: ='2.2 - Pont thermiques'!E29 -> 0.18 | G9: 1 | H9: =IF(C9="-",F9*D9*G9,C9*E9*G9) -> 5.7672
B10: Liaison mur/refend | C10: - | D10: 0 | E10: - | F10: 0.41 | G10: 1 | H10: =IF(C10="-",F10*D10*G10,C10*E10*G10) -> 0
B11: Parois opaques | H11: =SUM(H12:H18) -> 60.32616
B12: Mur extérieur | C12: =43.475+64.56+36.54 -> 144.575 | D12: - | E12: 0.3 | F12: - | G12: 1 | H12: =IF(C12="-",F12*D12*G12,C12*E12*G12) -> 43.3725
B13: Cloison séparative cellier | C13: 9.48 | D13: - | E13: 0.31 | F13: - | G13: =b -> 0.04 | H13: =IF(C13="-",F13*D13*G13,C13*E13*G13) -> 0.117552
B14: Cloison cellier/WC | C14: 3.93 | D14: - | E14: 0.42 | F14: - | G14: =b -> 0.04 | H14: =IF(C14="-",F14*D14*G14,C14*E14*G14) -> 0.066024
B15: Plancher bas RDC | C15: 51.4 | D15: - | E15: 0.15 | F15: - | G15: 1 | H15: =IF(C15="-",F15*D15*G15,C15*E15*G15) -> 7.71
B16: Plancher haut sur cellier | C16: 5.47 | D16: - | E16: 0.18 | F16: - | G16: =b -> 0.04 | H16: =IF(C16="-",F16*D16*G16,C16*E16*G16) -> 0.039384
B17: Plafond rampant combles | C17: 70.13 | D17: - | E17: 0.09 | F17: - | G17: 1 | H17: =IF(C17="-",F17*D17*G17,C17*E17*G17) -> 6.3117
B18: Porte d'entrée | C18: 1.935 | D18: - | E18: 1.4 | F18: - | G18: 1 | H18: =IF(C18="-",F18*D18*G18,C18*E18*G18) -> 2.709
B19: Parois vitrées | H19: =SUM(H20:H24) -> 43.88216
B20: Fenetres et portes fenetres | C20: ='1 - Métré des Surfaces Étudiées'!C4+'1 - Métré des Surfaces Étudiées'!C5+'1 - Métré des Surfaces Étudiées'!C6+'1 - Métré des Surfaces Étudiées'!C7 -> 27.7196 | D20: - | E20: 1.3 | F20: - | G20: 1 | H20: =IF(C20="-",F20*D20*G20,C20*E20*G20) -> 36.03548
B21: Porte cuisine vers extérieur | C21: ='1 - Métré des Surfaces Étudiées'!F5 -> 1.935 | D21: - | E21: 1.4 | F21: - | G21: 1 | H21: =IF(C21="-",F21*D21*G21,C21*E21*G21) -> 2.709
B22: Porte d'entrée | C22: ='1 - Métré des Surfaces Étudiées'!F4 -> 1.935 | D22: - | E22: ='2 - Propriétés des Paroies'!L17 -> 1.4 | F22: - | G22: 1 | H22: =IF(C22="-",F22*D22*G22,C22*E22*G22) -> 2.709
B23: Porte coulissante vers cellier | C23: ='1 - Métré des Surfaces Étudiées'!F6 -> 1.7136 | D23: - | E23: ='2 - Propriétés des Paroies'!L19 -> 1.4 | F23: - | G23: 1 | H23: =IF(C23="-",F23*D23*G23,C23*E23*G23) -> 2.39904
B24: {='1 - Métré des Surfaces Étudiées'!B8:C8} -> Local non chauffé (celier) | C24: 0.57 | D24: - | E24: ='2 - Propriétés des Paroies'!L20 -> 1.3 | F24: - | G24: =b -> 0.04 | H24: =IF(C24="-",F24*D24*G24,C24*E24*G24) -> 0.02964
B25: Perte par renouvellement d'air (PRA) | H25: =HRA -> 75
B26: Déperditions totales H = Pi UiSibi + Pj ΨjLjbj + HRA = | H26: =SUM(H25,H19,H11,H3) -> 233.89246
D28: On a estimé le déperditions du bâtiment à : | H28: =H26*(Tint-Text) -> 7016.7738
D29: On major donc la puissance de chauffage à : | H29: =H28*1.2/1000 -> 8.4201286

Sheet 6 - Analyse Pleiades
B2: Solution de base | C2: Puissance (kW) | E2: Epaisseur isolant (cm) | F2: Puissance déperditives
B3: WC autre | C3: 0.07 | E3: 5 | F3: 7.73
B4: Rangement | C4: 0.13 | E4: 10 | F4: 6.5
B5: Douche WC | C5: 0.17 | E5: 15 | F5: 6.02
B6: WC | C6: 0.17 | E6: 20 | F6: 5.76
B7: Dressing | C7: 0.18 | E7: 25 | F7: 5.59
B8: Bain | C8: 0.22 | E8: 30 | F8: 5.47
B9: CH 1 | C9: 0.83
B10: CH 2 | C10: 0.85
B11: CH 3 | C11: 0.99
B12: Suite parentale | C12: 1.03
B13: Séjour | C13: 3.48
B14: Général | C14: 6.5
B29: Général via Excel : | C29: ='5 - Calcul des déperditions'!H28/1000 -> 7.0167738
B34: =(C29-C14)/C29 -> 0.073648348

Sheet 7 - Dim. des chauffages

Sheet 7 - Calculs Dim. du chauffage
B2: Le régime d’eau étant 45/40/19, on fixe : | E2: Te = | F2: 45
E3: Ts = | F3: 40
E4: Ti = | F4: 19
B6: On calcul donc TLM : | C6: ΔTLM = | D6: =(_Te+_Ts)/2-_Ti -> 23.5
B8: Ensuite, comme on a fixé le modèle (radiateur vertical de gamme KOS V / FARO V), le type (21) et la hauteur (2100 mm), la seule dimension à déterminer est la largeur.
B12: On vérifie le TLMN du chauffage étudié : | E12: TeN = | F12: 55 | G12: ΔTLMN = | H12: =(F12+F13)/2-F14 -> 30
E13: TsN = | F13: 45
E14: TiN = | F14: 20
B24: KOSV ou FARO V Type 20
B25: Coef n | G25: Puissance 55/45/20 ΔT=30K [W]
B26: Largeur | C26: 1500 | D26: 1800 | E26: 1950 | F26: 2100 | G26: 1500 | H26: 1800 | I26: 1950 | J26: 2100
B27: 300 | C27: - | D27: 1.276 | E27: 1.2753 | F27: 1.2671 | G27: - | H27: 459 | I27: 495 | J27: 532
B28: 450 | C28: - | D28: 1.2818 | E28: 1.2802 | F28: 1.2746 | G28: - | H28: 657 | I28: 709 | J28: 761
B29: 600 | C29: - | D29: 1.2876 | E29: 1.2851 | F29: 1.2822 | G29: - | H29: 847 | I29: 914 | J29: 980
B30: 750 | C30: - | D30: 1.2934 | E30: 1.29 | F30: 1.2897 | G30: - | H30: 1031 | I30: 1113 | J30: 1191
B32: KOSV ou FARO V Type 21
B33: Coef n | G33: Puissance 55/45/20 ΔT=30K [W]
B34: Largeur | C34: 1500 | D34: 1800 | E34: 1950 | F34: 2100 | G34: 1500 | H34: 1800 | I34: 1950 | J34: 2100
B35: 300 | C35: 1.2964 | D35: 1.2876 | E35: 1.2905 | F35: 1.2935 | G35: 456 | H35: 495 | I35: 521 | J35: 548
B36: 450 | C36: 1.2984 | D36: 1.2965 | E36: 1.2954 | F36: 1.2942 | G36: 634 | H36: 716 | I36: 756 | J36: 796
B37: 600 | C37: 1.3005 | D37: 1.3054 | E37: 1.3003 | F37: 1.2952 | G37: 826 | H37: 930 | I37: 935 | J37: 1038
B38: 750 | C38: 1.3025 | D38: 1.3143 | E38: 1.3052 | F38: 1.2961 | G38: 1014 | H38: 1139 | I38: 1207 | J38: 1276
B40: KOSV ou FARO V Type 22
B41: Coef n | G41: Puissance 55/45/20 ΔT=30K [W]
B42: Largeur | C42: 1500 | D42: 1800 | E42: 1950 | F42: 2100 | G42: 1500 | H42: 1800 | I42: 1950 | J42: 2100
B43: 300 | C43: 1.3062 | D43: 1.2958 | E43: 1.2917 | F43: 1.2876 | G43: 521 | H43: 592 | I43: 624 | J43: 655
B44: 450 | C44: 1.3101 | D44: 1.5019 | E44: 1.2976 | F44: 1.2934 | G44: 769 | H44: 873 | I44: 921 | J44: 967
B45: 600 | C45: 1.5139 | D45: 1.3079 | E45: 1.3035 | F45: 1.2991 | G45: 1014 | H45: 1149 | I45: 1213 | J45: 1273
B46: 750 | C46: 1.5178 | D46: 1.314 | E46: 1.3095 | F46: 1.3049 | G46: 1255 | H46: 1421 | I46: 1500 | J46: 1574
B48: Gamme Banga
B49: Référence | C49: Nb de tubes | D49: Largeur | E49: Hauteur | F49: EH | G49: EV | H49: Entraxe alimentation EC | I49: Poids [kg] | J49: Volume [L] | K49: Coef n | L49: ΔT = 50°C | M49: ΔT = 30°C
B50: BAN1550C/CM | C50: 15 | D50: 500 | E50: 862 | F50: 350 | G50: 727 | H50: 455/50 | I50: 6 | J50: 3.6 | K50: 1.276 | L50: 374 | M50: 195
B51: BAN2150C/CM | C51: 21 | D51: 500 | E51: 1222 | F51: 350 | G51: 1087 | H51: 455/50 | I51: 8.9 | J51: 5 | K51: 1.265 | L51: 528 | M51: 278
B52: BAN2660C/CM | C52: 26 | D52: 600 | E52: 1537 | F52: 450 | G52: 1402 | H52: 555/50 | I52: 14.1 | J52: 7.1 | K52: 1.244 | L52: 758 | M52: 402
B53: BAN3050C/CM | C53: 30 | D53: 500 | E53: 1537 | F53: 350 | G53: 1402 | H53: 455/50 | I53: 13.2 | J53: 6.8 | K53: 1.252 | L53: 689 | M53: 363
B54: BAN3260C/CM | C54: 32 | D54: 600 | E54: 1807 | F54: 450 | G54: 1672 | H54: 555/50 | I54: 14.2 | J54: 8.6 | K54: 1.23 | L54: 921 | M54: 491
B55: BAN3675C/CM | C55: 36 | D55: 750 | E55: 1807 | F55: 600 | G55: 1672 | H55: 705/50 | I55: 20.2 | J55: 11 | K55: 1.24 | L55: 1183 | M55: 618
B58: Donc on obtient les puissances corrigées suivantes : | E58: Puissance KOSV ou FARO V Type 20 corrigée | K58: Puissance KOSV ou FARO V Type 21 corrigée | Q58: Puissance KOSV ou FARO V Type 22 corrigée | W58: Gamme Banga corrigée
E59: Largeur | F59: Hauteur | K59: Largeur | L59: Hauteur | Q59: Largeur | R59: Hauteur | W59: Référence | X59: Largeur | Y59: Hauteur | Z59: Puissance ΔT = 23,5°C
F60: 1500 | G60: 1800 | H60: 1950 | I60: 2100 | L60: 1500 | M60: 1800 | N60: 1950 | O60: 2100 | R60: 1500 | S60: 1800 | T60: 1950 | U60: 2100
...

Sheet 8 - Dim. Plancher chauffant

Sheet 9 - Loi d'eau
